Workbook

Sheet Macro
I1: Projetado
A2: Macro | D2: 2020 | E2: 2021 | F2: 2022 | G2: 2023 | H2: 2024 | I2: 2025 | J2: 2026 | K2: 2027 | L2: 2028 | M2: 2029 | N2: 2030
B4: =CHOOSE($C$11,B13,B20,B27) -> [2] Cenário Base
B5: IPCA | D5: 0.0452 | E5: 0.1006 | F5: 0.0579 | G5: 0.0462 | H5: 0.0483 | I5: 0.055 | J5: 0.045 | K5: 0.04 | L5: 0.038 | M5: 0.04 | N5: 0.04
B6: Selic | D6: 0.02 | E6: 0.0442 | F6: 0.1239 | G6: 0.1304 | H6: 0.1088 | I6: 0.1475 | J6: 0.125 | K6: 0.105 | L6: 0.1 | M6: =L6 -> 0.1 | N6: =M6 -> 0.1
B7: PIB | D7: -0.033 | E7: 0.048 | F7: 0.03 | G7: 0.032 | H7: 0.034 | I7: 0.0202 | J7: 0.017 | K7: 0.02 | L7: 0.02 | M7: =L7 -> 0.02 | N7: =M7 -> 0.02
B8: Câmbio | D8: 5.22 | E8: 5.67 | F8: 5.29 | G8: 4.84 | H8: 6.19 | I8: 5.82 | J8: 5.9 | K8: 5.8 | L8: 5.85 | M8: =L8 -> 5.85 | N8: =M8 -> 5.85
B9: Minério de Ferro US$/t | D9: 155.6 | E9: 121.05 | F9: 127.85 | G9: 131.05 | H9: 106.25 | I9: 100 | J9: 95 | K9: 90 | L9: =AVERAGE(I9:K9) -> 95 | M9: =L9 -> 95 | N9: =M9 -> 95
B11: Escolher Cenário | C11: 2 | E11: [1] Cenário Pessimista / [2] Cenário Base / [3] Cenário Otimista
B13: [1] Cenário Pessimista
B14: IPCA | D14: 0.0452 | E14: 0.1006 | F14: 0.0579 | G14: 0.0462 | H14: 0.0483
B15: Selic | D15: 0.02 | E15: 0.0442 | F15: 0.1239 | G15: 0.1304 | H15: 0.1088
B16: PIB | D16: -0.033 | E16: 0.048 | F16: 0.03 | G16: 0.032 | H16: 0.034
B17: Câmbio | D17: 5.22 | E17: 5.67 | F17: 5.29 | G17: 4.84 | H17: 6.19
B18: Minério de Ferro US$/t | D18: 155.6 | E18: 121.05 | F18: 127.85 | G18: 131.05 | H18: 106.25
B20: [2] Cenário Base
B21: IPCA | D21: 0.0452 | E21: 0.1006 | F21: 0.0579 | G21: 0.0462 | H21: 0.0483
B22: Selic | D22: 0.02 | E22: 0.0442 | F22: 0.1239 | G22: 0.1304 | H22: 0.1088
B23: PIB | D23: -0.033 | E23: 0.048 | F23: 0.03 | G23: 0.032 | H23: 0.034
B24: Câmbio | D24: 5.22 | E24: 5.67 | F24: 5.29 | G24: 4.84 | H24: 6.19
B25: Minério de Ferro US$/t | D25: 155.6 | E25: 121.05 | F25: 127.85 | G25: 131.05 | H25: 106.25
B27: [2] Cenário Otimista
B28: IPCA | D28: 0.0452 | E28: 0.1006 | F28: 0.0579 | G28: 0.0462 | H28: 0.0483
B29: Selic | D29: 0.02 | E29: 0.0442 | F29: 0.1239 | G29: 0.1304 | H29: 0.1088
B30: PIB | D30: -0.033 | E30: 0.048 | F30: 0.03 | G30: 0.032 | H30: 0.034
B31: Câmbio | D31: 5.22 | E31: 5.67 | F31: 5.29 | G31: 4.84 | H31: 6.19
B32: Minério de Ferro US$/t | D32: 155.6 | E32: 121.05 | F32: 127.85 | G32: 131.05 | H32: 106.25

Sheet Dados Financeiros
J1: Projetado
B2: Dados Financeiros | E2: 2020 | F2: 2021 | G2: 2022 | H2: 2023 | I2: 2024 | J2: 2025 | K2: 2026 | L2: 2027 | M2: 2028 | N2: 2029 | O2: 2030
B5: Premissas
B7: Crescimento Receita (Var. %) | F7: =F24/E24-1 -> 0.42419626 | G7: =G24/F24-1 -> -0.22831523 | H7: =H24/G24-1 -> -0.081418758 | I7: =I24/H24-1 -> -0.0099055108 | J7: =Macro!I5 -> 0.055 | K7: =Macro!J5 -> 0.045 | L7: =Macro!K5 -> 0.04 | M7: =Macro!L5 -> 0.038 | N7: =Macro!M5 -> 0.04 | O7: =Macro!N5 -> 0.04
B8: CPV (% Receita) | E8: =-E25/E24 -> 0.36076041 | F8: =-F25/F24 -> 0.34371295 | G8: =-G25/G24 -> 0.47599202 | H8: =-H25/H24 -> 0.50328261 | I8: =-I25/I24 -> 0.55723405 | J8: =AVERAGE(G8:I8) -> 0.51216956 | K8: =J8 -> 0.51216956 | L8: =K8 -> 0.51216956 | M8: =L8 -> 0.51216956 | N8: =M8 -> 0.51216956 | O8: =N8 -> 0.51216956
B9: Despesas com Vendas/Administrativas (% Receita Líq.) | E9: =-E27/E24 -> 0.012270861 | F9: =-F27/F24 -> 0.0088612856 | G9: =-G27/G24 -> 0.011734685 | H9: =-H27/H24 -> 0.013255409 | I9: =-I27/I24 -> 0.016489891 | J9: =AVERAGE(E9:I9) -> 0.012522426 | K9: =J9 -> 0.012522426 | L9: =K9 -> 0.012522426 | M9: =L9 -> 0.012522426 | N9: =M9 -> 0.012522426 | O9: =N9 -> 0.012522426
B10: Despesas com P&D (% Receita Líq.) | E10: =-E28/E24 -> 0.010436783 | F10: =-F28/F24 -> 0.010097982 | G10: =-G28/G24 -> 0.015059071 | H10: =-H28/H24 -> 0.01729259 | I10: =-I28/I24 -> 0.02090726 | J10: =I10 -> 0.02090726 | K10: =J10 -> 0.02090726 | L10: =K10 -> 0.02090726 | M10: =L10 -> 0.02090726 | N10: =M10 -> 0.02090726 | O10: =N10 -> 0.02090726
B11: Outras Receitas (Despesas) Operacionais | E11: =E31 -> -4202 | F11: =F31 -> -2212 | G11: =G31 -> -8901 | H11: =H31 -> -7422 | I11: =I31 -> -8275 | J11: =AVERAGE(E11:I11) -> -6202.4 | K11: =J11 -> -6202.4 | L11: =K11 -> -6202.4 | M11: =L11 -> -6202.4 | N11: =M11 -> -6202.4 | O11: =N11 -> -6202.4
B12: Depreciação (% Imobilizado) | E12: =-E33/E63 -> 0.063312289 | F12: =-F33/F63 -> 0.057615326 | G12: =-G33/G63 -> 0.056892665 | H12: =-H33/H63 -> 0.052647697 | I12: =-I33/I63 -> 0.052846347 | J12: =I12 -> 0.052846347 | K12: =J12 -> 0.052846347 | L12: =K12 -> 0.052846347 | M12: =L12 -> 0.052846347 | N12: =M12 -> 0.052846347 | O12: =N12 -> 0.052846347
B13: Aliquota de Depreciação | F13: =-F33/((F63+E63)/2) -> 0.059949453 | G13: =-G33/((G63+F63)/2) -> 0.057251715 | H13: =-H33/((H63+G63)/2) -> 0.052895053 | I13: =-I33/((I63+H63)/2) -> 0.054781124 | J13: =I13 -> 0.054781124 | K13: =J13 -> 0.054781124 | L13: =K13 -> 0.054781124 | M13: =L13 -> 0.054781124 | N13: =M13 -> 0.054781124 | O13: =N13 -> 0.054781124
B14: Juros (% Dívida) | E14: =-(E36+E37)/(E67+E74) -> 0.19332036 | F14: =-(F36+F37)/(F67+F74) -> 0.092576942 | G14: =-(G36+G37)/(G67+G74) -> 0.052329263 | H14: =-(H36+H37)/(H67+H74) -> 0.084753623 | I14: =-(I36+I37)/(I67+I74) -> 0.062086508 | J14: =AVERAGE(G14:I14) -> 0.066389798 | K14: =J14 -> 0.066389798 | L14: =K14 -> 0.066389798 | M14: =L14 -> 0.066389798 | N14: =M14 -> 0.066389798 | O14: =N14 -> 0.066389798
B15: Imposto de Renda (% LAIR) | E15: =-E40/E39 -> 0.12048224 | F15: =-F40/F39 -> 0.15909819 | G15: =-G40/G39 -> 0.14930583 | H15: =-H40/H39 -> 0.27000756 | I15: =-I40/I39 -> 0.11082866 | J15: 0.13 | K15: 0.13 | L15: 0.13 | M15: 0.13 | N15: 0.13 | O15: 0.13
B16: PMR (dias) | E16: =E56*365/E24 -> 45.94688 | F16: =F56*365/F24 -> 27.158256 | G16: =G56*365/G24 -> 36.31662 | H16: =H56*365/H24 -> 35.641119 | I16: =I56*365/I24 -> 25.868304 | J16: =AVERAGE(G16:I16) -> 32.608681 | K16: =J16 -> 32.608681 | L16: =K16 -> 32.608681 | M16: =L16 -> 32.608681 | N16: =M16 -> 32.608681 | O16: =N16 -> 32.608681 | R16: 103.6
B17: PME (dias) | E17: =-E58*365/E25 -> 103.59634 | F17: =-F58*365/F25 -> 88.381026 | G17: =-G58*365/G25 -> 79.170902 | H17: =-H58*365/H25 -> 79.050336 | I17: =-I58*365/I25 -> 90.660972 | J17: =AVERAGE(G17:I17) -> 82.960737 | K17: =J17 -> 82.960737 | L17: =K17 -> 82.960737 | M17: =L17 -> 82.960737 | N17: =M17 -> 82.960737 | O17: =N17 -> 82.960737
B18: PMP (dias) | E18: =-E66*365/E25 -> 85.889283 | F18: =-F66*365/F25 -> 70.161417 | G18: =-G66*365/G25 -> 78.805279 | H18: =-H66*365/H25 -> 88.963434 | I18: =-I66*365/I25 -> 83.360527 | J18: =AVERAGE(G18:I18) -> 83.709747 | K18: =J18 -> 83.709747 | L18: =K18 -> 83.709747 | M18: =L18 -> 83.709747 | N18: =M18 -> 83.709747 | O18: =N18 -> 83.709747
B19: Capex (R$) | E19: 21720 | F19: 27301 | G19: 28184 | H19: 29446 | I19: 35098 | J19: =I19*(1+J13) -> 37020.708 | K19: =J19*(1+K13) -> 39048.744 | L19: =K19*(1+L13) -> 41187.878 | M19: =L19*(1+M13) -> 43444.196 | N19: =M19*(1+N13) -> 45824.118 | O19: =N19*(1+O13) -> 48334.415
B22: DRE
B24: Receita Líquida | E24: 206098 | F24: 293524 | G24: 226508 | H24: 208066 | I24: 206005 | J24: =I24*(1+J7) -> 217335.27 | K24: =J24*(1+K7) -> 227115.36 | L24: =K24*(1+L7) -> 236199.98 | M24: =L24*(1+M7) -> 245175.58 | N24: =M24*(1+N7) -> 254982.6 | O24: =N24*(1+O7) -> 265181.9
B25: CPV | E25: =-90949-E33 -> -74352 | F25: =-117267-F33 -> -100888 | G25: =-124195-G33 -> -107816 | H25: =-120016-H33 -> -104716 | I25: =-131318-I33 -> -114793 | J25: =-J24*J8 -> -111312.51 | K25: =-K24*K8 -> -116321.58 | L25: =-L24*L8 -> -120974.44 | M25: =-M24*M8 -> -125571.47 | N25: =-N24*N8 -> -130594.33 | O25: =-O24*O8 -> -135818.1
B26: Lucro Bruto | E26: =E24+E25 -> 131746 | F26: =F24+F25 -> 192636 | G26: =G24+G25 -> 118692 | H26: =H24+H25 -> 103350 | I26: =I24+I25 -> 91212 | J26: =J24+J25 -> 106022.76 | K26: =K24+K25 -> 110793.79 | L26: =L24+L25 -> 115225.54 | ... O26: =O24+O25 -> 129363.8
B27: Despesa com vendas e administrativas | E27: -2529 | F27: -2601 | G27: -2658 | H27: -2758 | I27: -3397 | J27: =-J24*J9 -> -2721.565 | K27: =-K24*K9 -> -2844.0354 | L27: =-L24*L9 -> -2957.7968 | M27: =-M24*M9 -> -3070.1931 | N27: =-N24*N9 -> -3193.0008 | O27: =-O24*O9 -> -3320.7209
B28: Pesquisa e desenvolvimento | E28: -2151 | F28: -2964 | G28: -3411 | H28: -3598 | I28: -4307 | J28: =-J24*J10 -> -4543.885 | K28: =-K24*K10 -> -4748.3598 | L28: =-L24*L10 -> -4938.2942 | M28: =-M24*M10 -> -5125.9494 | N28: =-N24*N10 -> -5330.9874 | O28: =-O24*O10 -> -5544.2269
B29: Pré-operacionais | E29: -4517 | F29: -3467 | G29: -2466 | H29: -2249 | I29: -2189 | J29: =I29 -> -2189 | K29: =J29 -> -2189 | L29: =K29 -> -2189 | M29: =L29 -> -2189 | N29: =M29 -> -2189 | O29: =N29 -> -2189
B30: Evento Brumadinho | E30: -27016 | F30: -14379
B31: Outras despesas operacionais | E31: -4202 | F31: -2212 | G31: -8901 | H31: -7422 | I31: -8275 | J31: =J11 -> -6202.4 | K31: =K11 -> -6202.4 | L31: =L11 -> -6202.4 | M31: =M11 -> -6202.4 | N31: =N11 -> -6202.4 | O31: =O11 -> -6202.4
B32: Redução/reversão ao valor recuperável | E32: -6968 | F32: -2352 | G32: 3833 | H32: -1317 | I32: 510 | J32: =AVERAGE(E32:I32) -> -1258.8 | K32: =AVERAGE(F32:J32) -> -116.96 | L32: =AVERAGE(G32:K32) -> 330.048 | M32: =AVERAGE(H32:L32) -> -370.5424 | N32: =AVERAGE(I32:M32) -> -181.25088 | O32: =AVERAGE(J32:N32) -> -319.50106
B33: Depreciação | E33: -16597 | F33: -16379 | G33: -16379 | H33: -15300 | I33: -16525 | J33: =-I63*J13+J19*J13/2 -> -16115.985 | K33: =-J63*K13+K19*K13/2 -> -18088.472 | L33: =-K63*L13+L19*L13/2 -> -20169.014 | M33: =-L63*M13+M19*M13/2 -> -22363.53 | N33: =-M63*N13+N19*N13/2 -> -24678.265 | O33: =-N63*O13+O19*O13/2 -> -27119.803
B34: Total de despesas | E34: =SUM(E27:E33) -> -63980 | F34: =SUM(F27:F33) -> -44354 | G34: =SUM(G27:G33) -> -29982 | H34: =SUM(H27:H33) -> -32644 | I34: =SUM(I27:I33) -> -34183 | J34: =SUM(J27:J33) -> -33031.635 | K34: =SUM(K27:K33) -> -34189.227 | L34: =SUM(L27:L33) -> -36126.457 | ... O34: =SUM(O27:O33) -> -44695.652
B35: EBIT | E35: =E26+E34 -> 67766 | F35: =F26+F34 -> 148282 | G35: =G26+G34 -> 88710 | H35: =H26+H34 -> 70706 | I35: =I26+I34 -> 57029 | J35: =J26+J34 -> 72991.128 | K35: =K26+K34 -> 76604.56 | L35: =L26+L34 -> 79099.082 | ... O35: =O26+O34 -> 84668.153
B36: Despesas financeiras | E36: -16666 | F36: -8942 | G36: -6156 | H36: -7276 | I36: -7968 | J36: =AVERAGE(E36:I36) -> -9401.6 | K36: =J36 -> -9401.6 | L36: =K36 -> -9401.6 | M36: =L36 -> -9401.6 | N36: =M36 -> -9401.6 | O36: =N36 -> -9401.6
B37: Receitas financeiras | E37: 1570 | F37: 1822 | G37: 2685 | H37: 2159 | I37: 2281 | J37: =AVERAGE(E37:I37) -> 2103.4 | K37: =J37 -> 2103.4 | L37: =K37 -> 2103.4 | M37: =L37 -> 2103.4 | N37: =M37 -> 2103.4 | O37: =N37 -> 2103.4
B38: Resultado não operacional | E38: -14266 | F38: 17985 | G38: 16465 | H38: -10035 | I38: -17118 | J38: =AVERAGE(E38:I38) -> -1393.8 | K38: =J38 -> -1393.8 | L38: =K38 -> -1393.8 | M38: =L38 -> -1393.8 | N38: =M38 -> -1393.8 | O38: =N38 -> -1393.8
B39: LAIR | E39: =E35+E36+E37+E38 -> 38404 | F39: =F35+F36+F37+F38 -> 159147 | G39: =G35+G36+G37+G38 -> 101704 | H39: =H35+H36+H37+H38 -> 55554 | I39: =I35+I36+I37+I38 -> 34224 | J39: =J35+J36+J37+J38 -> 64299.128 | K39: =K35+K36+K37+K38 -> 67912.56 | L39: =L35+L36+L37+L38 -> 70407.082 | ... O39: =O35+O36+O37+O38 -> 75976.153
B40: IR | E40: -4627 | F40: -25320 | G40: -15185 | H40: -15000 | I40: -3793 | J40: =-J39*J15 -> -8358.8867 | K40: =-K39*K15 -> -8828.6328 | L40: =-L39*L15 -> -9152.9207 | M40: =-M39*M15 -> -9306.7643 | N40: =-N39*N15 -> -9609.7781 | O40: =-O39*O15 -> -9876.8999
B41: Resultado operações descontinuadas | E41: -7065 | F41: -11417 | G41: 9818
B42: Lucro Líquido | E42: =E39+E40+E41 -> 26712 | F42: =F39+F40+F41 -> 122410 | G42: =G39+G40+G41 -> 96337 | H42: =H39+H40+H41 -> 40554 | I42: =I39+I40+I41 -> 30431 | J42: =J39+J40+J41 -> 55940.242 | K42: =K39+K40+K41 -> 59083.928 | L42: =L39+L40+L41 -> 61254.161 | ... O42: =O39+O40+O41 -> 66099.253
B44: EBITDA Ajustado | E44: 87340 | F44: 168056 | G44: 102057 | H44: 92594 | I44: 80121
B45: Margem EBITDA Ajustado | E45: =E44/E24 -> 0.42377898 | F45: =F44/F24 -> 0.57254603 | G45: =G44/G24 -> 0.45056687 | H45: =H44/H24 -> 0.44502225 | I45: =I44/I24 -> 0.38892745
B46: EBIT Ajustado | E46: 70661 | F46: 151677 | G46: 85671 | H46: 77294 | I46: 63596
B47: Margem EBIT Ajustado | E47: =E46/E24 -> 0.34285146 | F47: =F46/F24 -> 0.5167448 | G47: =G46/G24 -> 0.37822505 | H47: =H46/H24 -> 0.37148789 | I47: =I46/I24 -> 0.30871095
...

Sheet Dados de Apoio para Gráficos
J1: Projetado
B2: Dados Financeiros | E2: 2020 | F2: 2021 | G2: 2022 | H2: 2023 | I2: 2024 | J2: 2025 | K2: 2026 | L2: 2027 | M2: 2028 | N2: 2029 | O2: 2030
B5: Premissas
B7: Receita minério de ferro (% Receita Líq.) | E7: =E16/'Dados Financeiros'!E24 -> 0.6913119 | F7: =F16/'Dados Financeiros'!F24 -> 0.70945476 | G7: =G16/'Dados Financeiros'!G24 -> 0.6433062 | H7: =H16/'Dados Financeiros'!H24 -> 0.66327992 | I7: =I16/'Dados Financeiros'!I24 -> 0.65209582
B8: Receita pelotas de minério de ferro (% Receita Líq.) | E8: =E17/'Dados Financeiros'!E24 -> 0.10695397 | F8: =F17/'Dados Financeiros'!F24 -> 0.12929437 | G8: =G17/'Dados Financeiros'!G24 -> 0.14238349 | H8: =H17/'Dados Financeiros'!H24 -> 0.13923947 | I8: =I17/'Dados Financeiros'!I24 -> 0.1548409
B9: Receita Outros minerais ferrosos (% Receita Líq.) | E9: =E18/'Dados Financeiros'!E24 -> 0.013799261 | F9: =F18/'Dados Financeiros'!F24 -> 0.010050285 | G9: =G18/'Dados Financeiros'!G24 -> 0.010706024 | H9: =H18/'Dados Financeiros'!H24 -> 0.012342238 | I9: =I18/'Dados Financeiros'!I24 -> 0.018921871
B10: Receita Níquel e outros produtos (% Receita Líq.) | E10: =E19/'Dados Financeiros'!E24 -> 0.12555677 | F10: =F19/'Dados Financeiros'!F24 -> 0.099303634 | G10: =G19/'Dados Financeiros'!G24 -> 0.15110283 | H10: =H19/'Dados Financeiros'!H24 -> 0.1250036 | I10: =I19/'Dados Financeiros'!I24 -> 0.096517075
B11: Receita cobre (% Receita Líq.) | E11: =E20/'Dados Financeiros'!E24 -> 0.055100001 | F11: =F20/'Dados Financeiros'!F24 -> 0.047617912 | G11: =G20/'Dados Financeiros'!G24 -> 0.040771187 | H11: =H20/'Dados Financeiros'!H24 -> 0.05688099 | I11: =I20/'Dados Financeiros'!I24 -> 0.073935099
B12: Receita outros (% Receita Líq.) | E12: =E21/'Dados Financeiros'!E24 -> 0.007278091 | F12: =F21/'Dados Financeiros'!F24 -> 0.0042790368 | G12: =G21/'Dados Financeiros'!G24 -> 0.01173027 | H12: =H21/'Dados Financeiros'!H24 -> 0.0032537752 | I12: =I21/'Dados Financeiros'!I24 -> 0.0036892308
B14: Receita Expandida
B16: Minério de Ferro | E16: 142478 | F16: 208242 | G16: 145714 | H16: 138006 | I16: 134335
B17: Pelotas de Minério de Ferro | E17: 22043 | F17: 37951 | G17: 32251 | H17: 28971 | I17: 31898
B18: Outros Minerais Ferrosos | E18: 2844 | F18: 2950 | G18: 2425 | H18: 2568 | I18: 3898
B19: Níquel e Outros | E19: 25877 | F19: 29148 | G19: 34226 | H19: 26009 | I19: 19883
B20: Cobre | E20: 11356 | F20: 13977 | G20: 9235 | H20: 11835 | I20: 15231
B21: Outros | E21: 1500 | F21: 1256 | G21: 2657 | H21: 677 | I21: 760
B23: Receita de vendas por área geográfica
B25: Américas (ex. EUA e Brasil) | G25: 6914 | H25: 6169 | I25: 5150
B26: EUA | G26: 8323 | H26: 8471 | I26: 5813
B27: Alemanha | G27: 11003 | H27: 7909 | I27: 8000
B28: Europa (ex. Alemanha) | G28: 25300 | H28: 19771 | I28: 16301
B29: Oriente Médio, África e Oceania | G29: 11600 | H29: 13663 | I29: 14299
B30: Japão | G30: 24399 | H30: 18239 | I30: 16466
B31: China | G31: 154067 | H31: 114960 | I31: 105200
B32: Ásia (ex. Japão e China) | G32: 24240 | H32: 16059 | I32: 15643
B33: Brasil | G33: 27678 | H33: 21267 | I33: 19133
B34: Receita Líquida | G34: =SUM(G25:G33) -> 293524 | H34: =SUM(H25:H33) -> 226508 | I34: =SUM(I25:I33) -> 206005
B36: CPV Expandido
B38: Pessoal
B39: Materiais e Serviços | G39: 9218 | H39: 9384 | I39: 14600
B40: Óleo combustível e gases | G40: 15705 | H40: 18797 | I40: 14907
B41: Manutenção | G41: 5472 | H41: 8446 | I41: 7523
B42: Royalties | G42: 15167 | H42: 16029 | I42: 24362
B43: Energia | G43: 7372 | H43: 6576 | I43: 6932
B44: Aquisição de minério de terceiros | G44: 3446 | H44: 3709 | I44: 3514
B45: Depreciação/Amortização | G45: 12214 | H45: 13247 | I45: 10745
B46: Frete | G46: 15430 | H46: 15753 | I46: 15689
B47: Outros | G47: 24744 | H47: 24494 | I47: 25832
B48: Total | G48: 8499 | H48: 7760 | I48: 7214
B50: Custos de Produção (US$/t)
...

Sheet WACC
B2: WACC
B5: Custo de Capital
B6: TLR | D6: 0.1395 | I6: Valor de Mercado
B7: Beta | D7: 1.06 | I7: Market Cap | J7: 232578
B8: Prêmio de risco | D8: 0.06 | I8: (+) Dívida | J8: =D12 -> 91598
B9: Alíquota de Juros sobre o CP | D9: 0.41 | I9: (-) Caixa | J9: ='Dados Financeiros'!I54 -> 30671
B10: CAPM | D10: =(D6+(D7*D8)*(1-D9*15%)) -> 0.1991886 | I10: EV | J10: =J7+J8-J9 -> 293505
B12: Dívida Total | D12: ='Dados Financeiros'!I67+'Dados Financeiros'!I74 -> 91598
B13: Equity Total | D13: =J7 -> 232578
B15: D/(D+E) | D15: =D12/(D12+D13) -> 0.28255639
B16: E/(D+E) | D16: =D13/(D12+D13) -> 0.71744361
B17: D/E | D17: =D15/D16 -> 0.39383777
B19: Custo do Capital Próprio | D19: =D10 -> 0.1991886
B20: Custo do Capital de Terceiros antes do IR | D20: 0.1518
B21: Custo do Capital de Terceiros após o IR | D21: 0.1063
B23: WACC | D23: =(D19*D16)+(D21*D15) -> 0.17294233

Sheet Valuation
B2: DCF
B5: DCF
B7: Premissas
B8: IR | D8: ='Dados Financeiros'!J15 -> 0.13
B9: Taxa de Desconto | D9: =WACC!D23 -> 0.17294233
B10: Crescimento na Perpetuidade | D10: =Macro!N5 -> 0.04
B11: Múltiplo EV/EBITDA | D11: =WACC!J10/'Dados Financeiros'!I44 -> 3.6632718
B12: Data do Valuation | D12: 45827
B13: Data Final do Ano | D13: 46022
B14: Preço Atual | D14: 51.24
B15: Ações Negociadas | D15: 4539
B17: Fluxo de Caixa Descontado | D17: Entrada | E17: 2025 | F17: =+E17+1 -> 2026 | G17: =+F17+1 -> 2027 | H17: =+G17+1 -> 2028 | I17: =+H17+1 -> 2029 | J17: 2030 | K17: Saída | M17: Terminal Value
B18: Data | D18: =+D12 -> 45827 | E18: =DATE(YEAR($D$18)+E19,MONTH($D$13),DAY($D$13)) -> 46022 | F18: =DATE(YEAR($D$18)+F19,MONTH($D$13),DAY($D$13)) -> 46387 | G18: =DATE(YEAR($D$18)+G19,MONTH($D$13),DAY($D$13)) -> 46752 | H18: =DATE(YEAR($D$18)+H19,MONTH($D$13),DAY($D$13)) -> 47118 | I18: =DATE(YEAR($D$18)+I19,MONTH($D$13),DAY($D$13)) -> 47483 | J18: =DATE(YEAR($D$18)+J19,MONTH($D$13),DAY($D$13)) -> 47848 | K18: =J18 -> 47848 | M18: EV/EBITDA | N18: =+D11*('Dados Financeiros'!O35-'Dados Financeiros'!O33) -> 409509.67
B19: Período | F19: 1 | G19: =F19+1 -> 2 | H19: =G19+1 -> 3 | I19: =H19+1 -> 4 | J19: =I19+1 -> 5 | M19: Gordon | N19: =(J36*(1+D10))/(D9-D10) -> 383087
B20: Fração do ano | E20: =YEARFRAC(D18,E18) -> 0.53333333 | F20: =YEARFRAC(E18,F18) -> 1 | G20: =YEARFRAC(F18,G18) -> 1 | H20: =YEARFRAC(G18,H18) -> 1 | I20: =YEARFRAC(H18,I18) -> 1 | J20: =YEARFRAC(I18,J18) -> 1 | M20: Média | N20: =AVERAGE(N18:N19) -> 396298.33
B22: EBIT | E22: 89107.113 | F22: 94693.032 | G22: 99268.096 | H22: 102646.02 | I22: 107291.63 | J22: 111787.96
B23: (-) IR | E23: -10453.965 | F23: -11180.134 | G23: -11774.892 | H23: -12214.023 | I23: -12817.952 | J23: -13402.474
B24: NOPAT | E24: 78653.148 | F24: 83512.898 | G24: 87493.203 | H24: 90432.001 | I24: 94473.682 | J24: 98385.482
B25: (+) Depreciação e Amortização | E25: 0 | F25: 0 | G25: 0 | H25: 0 | I25: 0 | J25: 0
B26: (-) Capex | E26: -37020.708 | F26: -39048.744 | G26: -41187.878 | H26: -43444.196 | I26: -45824.118 | J26: -48334.415
B27: (+/-) Var. Capital de Giro | E27: -18335.884 | F27: -206.94058 | G27: -2371.9275 | H27: -1619.8529 | I27: 408.58079 | J27: -1081.3747
B28: (-) Variação nos ativos | E28: -16768.893 | F28: -1355.728 | G28: -3439.0234 | H28: -2674.1436 | I28: -743.37052 | J28: -2279.404
B29: (-) Contas a receber | E29: -4816.484 | F29: -873.74178 | G29: -811.60903 | H29: -801.86972 | I29: -876.14818 | J29: -911.19411
B30: (-) Estoque | E30: 3212.8136 | F30: -1138.5084 | G30: -1057.5478 | H30: -1044.8572 | I30: -1141.644 | J30: -1187.3098
B31: (-) Outros | E31: -15165.222 | F31: 656.52219 | G31: -1569.8665 | H31: -827.41668 | I31: 1274.4216 | J31: -180.90019
B32: (+) Variação nos Passivos | E32: -1566.9912 | F32: 1148.7874 | G32: 1067.0958 | H32: 1054.2907 | I32: 1151.9513 | J32: 1198.0294
B33: (+) Contas a pagar | E33: -688.39118 | F33: 1148.7874 | G33: 1067.0958 | H33: 1054.2907 | I33: 1151.9513 | J33: 1198.0294
... B35: (+) Outros passivos | E35: -1444.2667 | F35: 0 | G35: 0 | H35: 0 | I35: 0 | J35: 0
B36: FREE CASH FLOW TO FIRM | E36: 23296.556 | F36: 44257.213 | G36: 43933.398 | H36: 45367.952 | I36: 49058.145 | J36: 48969.692 | K36: =N20 -> 396298.33
B38: FCFF sensibilizado pelo período | D38: 0 | E38: =+E36*E20 -> 12424.83 | F38: =F36*F20 -> 44257.213 | G38: =G36*G20 -> 43933.398 | H38: =H36*H20 -> 45367.952 | I38: =I36*I20 -> 49058.145 | J38: =J36*J20 -> 48969.692 | K38: =K36 -> 396298.33
B40: TIR FCFF | E40: =E38 -> 12424.83 | F40: =F38 -> 44257.213 | G40: =G38 -> 43933.398 | H40: =H38 -> 45367.952 | I40: =I38 -> 49058.145 | J40: =J38 -> 48969.692 | K40: =K38 -> 396298.33
B42: Valor Intrínseco
B44: Enterprise Value | D44: =XNPV(D9,D38:K38,D18:K18) -> 309073.34
B45: (+) Caixa | D45: ='Dados Financeiros'!I54 -> 30671
B46: (-) Dívida | D46: =WACC!J8 -> 91598 | I46: Sensitivity Analysis
B47: Equity Value | D47: =D44+D45-D46 -> 248146.34 | H47: WACC
G48: g | H48: =D49 -> 54.669825 | I48: =J48+1% -> 0.1929 | J48: =K48+1% -> 0.1829 | K48: 0.1729 | L48: =K48-2% -> 0.1529 | M48: =L48-2% -> 0.1329
B49: Equity/Ação | D49: =D47/D15 -> 54.669825 | H49: =H50-0.5% -> 0.03 | I49: 46.801775 | J49: 49.891425 | K49: 53.30847 | L49: 61.39958 | M49: 71.879328
B50: Upside | D50: =D49/D14-1 -> 0.066936482 | H50: =H51-0.5% -> 0.035 | I50: 47.27281 | J50: 50.448056 | K50: 53.972327 | L50: 62.375678 | M50: 73.399325
H51: 0.04 | I51: 47.774651 | J51: 51.04364 | K51: 54.686136 | L51: 63.438234 | M51: 75.082938
...
