Workbook
Name Case_Cell: [1]Inputs!$F$9
Name Case_Number: [1]Inputs!$E$9
Name Company_Name: [1]Inputs!$E$4
Name Comps_Range: '[1]Public-Comps-Data'!$D$2:$AA$106
Name Days_in_Year: [1]Inputs!$E$14
Name Equity_Interest_Value: '[1]YHOO-Equity-Interests'!$E$24
Name Forward_Year_1: [1]Inputs!$L$13
Name Forward_Year_2: [1]Inputs!$L$14
Name Forward_Year_3: [1]Inputs!$L$15
Name FYear_1_Name: [1]Inputs!$I$13
Name FYear_2_Name: [1]Inputs!$I$14
Name Hist_Year: [1]Inputs!$E$6
Name MA_Comps_Range: '[1]M&A-Comps-Data'!$D$2:$AK$84
Name Q4_Stub: [1]DCF!$P$4
Name Tax_Rate: [1]Inputs!$L$4
Name Ticker: [1]Inputs!$E$5
Name TTM: [1]Inputs!$L$12
Name Units: [1]Inputs!$E$15
Name WACC: #REF!
Name x: [2]Inputs!$L$12

Sheet Histórico
E2: Histórico | F2: Histórico | G2: Histórico | H2: Histórico
D3: Unit | E3: 2015 | F3: 2016 | G3: 2017 | H3: 2018
B4: DEMONSTRATIVO DE RESULTADOS
C5: Receita Bruta | D5: [R$] | E5: 249785250 | F5: 3.1389056e+08 | G5: 3.5301393e+08 | H5: 4.1868751e+08
C6: # produtos vendidos | D6: [#] | E6: 121550 | F6: 146870 | G6: 154370 | H6: 174370
C8: Deduções | D8: [R$] | E8: -60114984 | F8: -76149851 | G8: -83452494 | H8: -1.0062457e+08
C9: Impostos sobre as vendas | D9: [R$] | E9: -58449748 | F9: -74580398 | G9: -81334410 | H9: -97972878
C10: Devoluções | D10: [R$] | E10: -1665235 | F10: -1569452.8 | G10: -2118083.6 | H10: -2651687.6
C12: Receita Líquida | D12: [R$] | E12: 1.8967027e+08 | F12: 2.3774071e+08 | G12: 2.6956144e+08 | H12: 3.1806295e+08
C14: Custo dos produtos vendidos | D14: [R$] | E14: -1.4924686e+08 | F14: -1.8176446e+08 | G14: -2.0878504e+08 | H14: -2.4609444e+08
E15: 0.98
C16: Custo produtos | D16: [R$] | E16: -1.4322686e+08 | F16: -1.7408371e+08 | G16: -2.0075902e+08 | H16: -2.363491e+08
C17: Pessoal | D17: [R$] | E17: -6020000 | F17: -7680750 | G17: -8026018 | H17: -9745335.6
C18: # funcionários | D18: [#] | E18: 172 | F18: 210 | G18: 211 | H18: 244
C20: Lucro Bruto | D20: [R$] | E20: 40423404 | F20: 55976256 | G20: 60776398 | H20: 71968511
C22: Despesas Operacionais (SG&A) | D22: [R$] | E22: -19277517 | F22: -22537634 | G22: -26102116 | H22: -29072444
C24: Despesas comerciais | D24: [R$] | E24: -10441128 | F24: -13126312 | G24: -16031489 | H24: -18181382
C25: Pessoal | D25: [R$] | E25: -2448000 | F25: -3144592 | G25: -3428891.7 | H25: -3987875.6
C26: # funcionários | D26: [#] | E26: 36 | F26: 44 | G26: 46 | H26: 51
C27: Comissões | D27: [R$] | E27: -4745919.8 | F27: -5650030.2 | G27: -7413292.6 | H27: -8373750.3
C28: Marketing | D28: [R$] | E28: -2747637.8 | F28: -3766686.8 | G28: -4659783.9 | H28: -5233593.9
C29: Outros | D29: [R$] | E29: -499570.5 | F29: -565003.02 | G29: -529520.9 | H29: -586162.52
C31: Despesas gerais e administrativas | D31: [R$] | E31: -8836389.4 | F31: -9411322.1 | G31: -10070627 | H31: -10891061
... C49: Resultado não-operacional | D49: [R$] | E49: 0 | F49: -1242590 | G49: -227000 | H49: -150000
C50: Outras receitas | D50: [R$] | G50: 200000 | H50: 45000
C51: Outras despesas | D51: [R$] | E51: 0 | F51: -1242590 | G51: -427000 | H51: -195000
C53: LAIR | D53: [R$] | E53: 12775555 | F53: 18724623 | G53: 23351788 | H53: 32679864
C54: IR/CSLL | D54: [R$] | E54: -4265757.7 | F54: -6263386.2 | G54: -7846200.7 | H54: -11045794
C56: Lucro Líquido | D56: [R$] | E56: 8509797 | F56: 12461236 | G56: 15505587 | H56: 21634070
D59: Unit | E59: 2015 | F59: 2016 | G59: 2017 | H59: 2018
B60: BALANÇO PATRIMONIAL
C61: ATIVO | D61: [R$] | E61: 1.0009875e+08 | F61: 1.4312784e+08 | G61: 1.4408256e+08 | H61: 1.5614796e+08
C62: ATVO CIRCULANTE | D62: [R$] | E62: 74008987 | F62: 1.1859014e+08 | G62: 1.1956703e+08 | H62: 1.3096122e+08
C63: Caixa e equivalentes | D63: [R$] | E63: 2529062 | F63: 25688122 | G63: 16852498 | H63: 9115958.5
C64: Contas a receber | D64: [R$] | E64: 47875506 | F64: 61295852 | G64: 67661004 | H64: 82574482
C65: Estoque | D65: [R$] | E65: 23075439 | F65: 30948215 | G65: 34575165 | H65: 38734992
C66: Outros | D66: [R$] | E66: 528980 | F66: 657956 | G66: 478362 | H66: 535791
C68: ATIVO NÃO CIRCULANTE | D68: [R$] | E68: 26089767 | F68: 24537700 | G68: 24515531 | H68: 25186741
C69: Imobilizado | D69: [R$] | E69: 42977454 | F69: 45771081 | G69: 50536769 | H69: 56440263
C70: (-) Depreciação acumulada | D70: [R$] | E70: -17190982 | F70: -21628409 | G70: -26443801 | H70: -31792653
...

Sheet WACC
A2: Company Comp Set
A3: Company Name | B3: 5 Year Beta (Beta alavancado) | C3: Tax Rate Imp. Renda (T) | D3: Debt/Equity % (D/E) | E3: Beta desalavancado
A4: EMPRESA A | B4: 1.2334984 | C4: 0.275 | D4: 0.55187359 | E4: =B4/(1+(D4)*(1-C4)) -> 0.88100212
A5: SCHNEIDER ELECTRIC SE | B5: 1.144376 | C5: 0.28611221 | D5: 0.36527382 | E5: =B5/(1+(D5)*(1-C5)) -> 0.90768416
A6: TOSHIBA CORP | B6: 1.0769046 | C6: 0.4 | D6: 2.1443166 | E6: =B6/(1+(D6)*(1-C6)) -> 0.47096532
A7: ITRON INC | B7: 1.0426642 | C7: 0.58579414 | D7: 0.46824265 | E7: =B7/(1+(D7)*(1-C7)) -> 0.8732905
A8: XYLEM INC | B8: 1.0804727 | C8: 0.23529411 | D8: 1.0729497 | E8: =B8/(1+(D8)*(1-C8)) -> 0.59350625
A9: ORACLE CORP | B9: 1.0527772 | C9: 0.22207657 | D9: 0.9176606 | E9: =B9/(1+(D9)*(1-C9)) -> 0.61426909
A10: HONEYWELL INTERNATIONAL INC | B10: 1.0763 | C10: 0.24845009 | D10: 0.80690536 | E10: =B10/(1+(D10)*(1-C10)) -> 0.66999512
A11: ABB LTD-REG | B11: 1.0218681 | C11: 0.27902822 | D11: 0.48953011 | E11: =B11/(1+(D11)*(1-C11)) -> 0.75529596
A12: MACQUARIE INFRASTRUCTURE COR | B12: 0.89746911 | C12: 0.31512077 | D12: 0.97853813 | E12: =B12/(1+(D12)*(1-C12)) -> 0.5373486
A13: HERKULES SA | B13: 0.82393318 | C13: 0.4 | D13: 0.43432564 | E13: =B13/(1+(D13)*(1-C13)) -> 0.65360638
A14: ESCO TECHNOLOGIES INC | B14: 0.9852408 | C14: 0.32940662 | D14: 0.17883009 | E14: =B14/(1+(D14)*(1-C14)) -> 0.87974033
A15: SIEMENS AG-REG | B15: 0.88617576 | C15: 0.27120476 | D15: 0.97776886 | E15: =B15/(1+(D15)*(1-C15)) -> 0.5174467
A17: Summary Statistics | B17: =B3 -> 5 Year Beta (Beta alavancado) | C17: =C3 -> Tax Rate Imp. Renda (T) | D17: =D3 -> Debt/Equity % (D/E) | E17: =E3 -> Beta desalavancado
A18: Média | B18: =AVERAGE(B4:B15) -> 1.0268067 | C18: =AVERAGE(C4:C15) -> 0.32062396 | D18: =AVERAGE(D4:D15) -> 0.78218459 | E18: =AVERAGE(E4:E15) -> 0.69617921
A20: Company Name | B20: Debt/Equity % (D/E) | C20: Tax Rate Imp. Renda (T) | D20: Beta desalavancado | E20: Beta realavancado
A21: Company Elektric | B21: =(Model!H119+Model!H123)/Model!H125 -> 0.44152202 | C21: 0.34 | D21: =E18 -> 0.69617921 | E21: =D21*(1+B21*(1-C21)) -> 0.89904899
A24: CAPM (Rf + B*(Rm - Rf) + Rs + Rp
A25: Risk Free (T-Bond) | B25: 0.0258 | C25: Taxa livre de risco
A26: Beta Elektric | B26: =E21 -> 0.89904899
A27: Equity Risk Premium (Rm - Rf) - USA | B27: 0.0549 | C27: Prêmio de risco de mercado
A28: BR Country Risk (Embi+) | B28: 0.0253 | C28: Risco país
A29: Liquidity Premium | B29: 0.03 | C29: Risco pela falta de liquidez quando comparada a empresas de capital aberto
A30: CAPM [Target.Co] - nominal USD | B30: =B25+B26*B27+B28+B29 -> 0.13045779
A32: CPI (Inflação projetada nos EUA) | B32: 0.021
A33: CAPM [Target.Co] - real USD | B33: =(1+B30)/(1+B32)-1 -> 0.10720645
A35: IPCA (Inflação projetada em BRL) | B35: 0.04
A36: CAPM [Target.Co] - BRL nominal | B36: =(1+B33)*(1+B35)-1 -> 0.15149471
A38: WACC [Target.Co] [(Ke x %Capital Próprio) + (Kd x % Capital de Terceiros)]
A39: Dívida Total - BRLmm | B39: =Model!H119+Model!H123 -> 34316854
A40: Equity Total - BRLmm | B40: =Model!H125 -> 77723992
A42: D / (D+E) | B42: =B39/(B39+B40) -> 0.30628878 | C42: % capital de terceiros (debt)
A43: E / (D+E) | B43: =B40/(B39+B40) -> 0.69371122 | C43: % capital próprio (equity)
A45: Kd | B45: 0.14
A46: Kd com Benefício Fiscal | B46: =B45*(1-C21) -> 0.0924
A48: WACC YoY nominal - BRL | B48: =B36*B43+B46*B42 -> 0.13339466

Sheet Model
E1: PROJETO ELEKTRIC
E2: Histórico | I2: Projeções
D3: Unit | E3: 2015 | F3: =E3+1 -> 2016 | G3: =F3+1 -> 2017 | H3: =G3+1 -> 2018 | I3: 2019E | J3: 2020E | K3: 2021E | L3: 2022E | M3: 2023E | N3: 2024E | O3: 2025E | P3: 2026E | R3: CAGR 16-24
B4: DEMONSTRATIVO DO RESULTADO
C5: Receita Bruta | D5: [R$] | E5: =Histórico!E5 -> 249785250 | F5: =Histórico!F5 -> 3.1389056e+08 | G5: =Histórico!G5 -> 3.5301393e+08 | H5: =Histórico!H5 -> 4.1868751e+08 | I5: =I8*I10 -> 4.8537881e+08 | J5: =J8*J10 -> 5.5673552e+08 | K5: =K8*K10 -> 6.2762223e+08 | L5: =L8*L10 -> 7.032891e+08 | M5: =M8*M10 -> 7.7524105e+08 | N5: =N8*N10 -> 8.4270926e+08 | O5: =O8*O10 -> 9.0801505e+08 | P5: =P8*P10 -> 9.706247e+08 | R5: =(#REF!/H5)^(1/8)-1 -> #REF!
C6: % crescimento | D6: [%] | F6: =F5/E5-1 -> 0.25664171 | G6: =G5/F5-1 -> 0.12464016 | H6: =H5/G5-1 -> 0.18603679 | I6: =I5/H5-1 -> 0.15928657 | J6: =J5/I5-1 -> 0.1470124 | K6: =K5/J5-1 -> 0.12732565 | L6: =L5/K5-1 -> 0.12056117 | M6: =M5/L5-1 -> 0.10230778 | ... P6: =P5/O5-1 -> 0.068952222
C8: # produtos vendidos | D8: [#] | E8: =Histórico!E6 -> 121550 | F8: =Histórico!F6 -> 146870 | G8: =Histórico!G6 -> 154370 | H8: =Histórico!H6 -> 174370 | I8: =H8+I9 -> 194370 | J8: =I8+J9 -> 214370 | K8: =J8+K9 -> 232370 | L8: =K8+L9 -> 250370 | M8: =L8+M9 -> 265370 | N8: =M8+N9 -> 277370 | O8: =N8+O9 -> 287370 | P8: =O8+P9 -> 295370
C9: Aumento de unidades vendidas | D9: [#] | F9: =F8-E8 -> 25320 | G9: =G8-F8 -> 7500 | H9: =H8-G8 -> 20000 | I9: 20000 | J9: 20000 | K9: 18000 | L9: 18000 | M9: 15000 | N9: 12000 | O9: 10000 | P9: 8000
C10: Preço médio | D10: [R$/unidade] | E10: =E5/E8 -> 2055 | F10: =F5/F8 -> 2137.2 | G10: =G5/G8 -> 2286.804 | H10: =H5/H8 -> 2401.1442 | I10: =H10*(1+I11) -> 2497.19 | J10: =I10*(1+J11) -> 2597.0776 | K10: =J10*(1+K11) -> 2700.9607 | L10: =K10*(1+L11) -> 2808.9991 | M10: =L10*(1+M11) -> 2921.3591 | N10: =M10*(1+N11) -> 3038.2134 | O10: =N10*(1+O11) -> 3159.742 | P10: =O10*(1+P11) -> 3286.1316
C11: Variação no preço médio | D11: [%] | F11: =F10/E10-1 -> 0.04 | G11: =G10/F10-1 -> 0.07 | H11: =H10/G10-1 -> 0.05 | I11: 0.04 | J11: =I11 -> 0.04 | K11: =J11 -> 0.04 | L11: =K11 -> 0.04 | M11: =L11 -> 0.04 | N11: =M11 -> 0.04 | O11: =N11 -> 0.04 | P11: =O11 -> 0.04
C13: Deduções | D13: [R$] | E13: =E15+E17 -> -60114984 | F13: =F15+F17 -> -76149851 | G13: =G15+G17 -> -83452494 | H13: =H15+H17 -> -1.0062457e+08 | I13: =I15+I17 -> -1.1665271e+08 | J13: =J15+J17 -> -1.338021e+08 | K13: =K15+K17 -> -1.5083854e+08 | L13: =L15+L17 -> -1.6902381e+08 | ... P13: =P15+P17 -> -2.3327347e+08
C14: % receita bruta | D14: [%] | E14: =E13/E$5 -> -0.24066667 | F14: =F13/F$5 -> -0.2426 | G14: =G13/G$5 -> -0.2364 | H14: =H13/H$5 -> -0.24033333 | I14: =I13/I$5 -> -0.24033333 | J14: =J13/J$5 -> -0.24033333 | K14: =K13/K$5 -> -0.24033333 | L14: =L13/L$5 -> -0.24033333 | ... P14: =P13/P$5 -> -0.24033333
C15: Impostos sobre as vendas | D15: [R$] | E15: =Histórico!E9 -> -58449748 | F15: =Histórico!F9 -> -74580398 | G15: =Histórico!G9 -> -81334410 | H15: =Histórico!H9 -> -97972878 | I15: =I$5*I16 -> -1.1357864e+08 | J15: =J$5*J16 -> -1.3027611e+08 | K15: =K$5*K16 -> -1.468636e+08 | L15: =L$5*L16 -> -1.6456965e+08 | M15: =M$5*M16 -> -1.8140641e+08 | N15: =N$5*N16 -> -1.9719397e+08 | O15: =O$5*O16 -> -2.1247552e+08 | P15: =P$5*P16 -> -2.2712618e+08
C16: % receita bruta | D16: [%] | E16: =E15/E$5 -> -0.234 | F16: =F15/F$5 -> -0.2376 | G16: =G15/G$5 -> -0.2304 | H16: =H15/H$5 -> -0.234 | I16: =H16 -> -0.234 | J16: =I16 -> -0.234 | K16: =J16 -> -0.234 | L16: =K16 -> -0.234 | M16: =L16 -> -0.234 | N16: =M16 -> -0.234 | O16: =N16 -> -0.234 | P16: =O16 -> -0.234
C17: Devoluções | D17: [R$] | E17: =Histórico!E10 -> -1665235 | F17: =Histórico!F10 -> -1569452.8 | G17: =Histórico!G10 -> -2118083.6 | H17: =Histórico!H10 -> -2651687.6 | I17: =I$5*I18 -> -3074065.8 | J17: =J$5*J18 -> -3525991.6 | K17: =K$5*K18 -> -3974940.8 | L17: =L$5*L18 -> -4454164.3 | M17: =M$5*M18 -> -4909860 | N17: =N$5*N18 -> -5337158.6 | O17: =O$5*O18 -> -5750762 | P17: =P$5*P18 -> -6147289.8
C18: % receita bruta | D18: [%] | E18: =E17/E$5 -> -0.0066666667 | F18: =F17/F$5 -> -0.005 | G18: =G17/G$5 -> -0.006 | H18: =H17/H$5 -> -0.0063333333 | I18: =H18 -> -0.0063333333 | J18: =I18 -> -0.0063333333 | K18: =J18 -> -0.0063333333 | L18: =K18 -> -0.0063333333 | M18: =L18 -> -0.0063333333 | N18: =M18 -> -0.0063333333 | O18: =N18 -> -0.0063333333 | P18: =O18 -> -0.0063333333
C20: Receita líquida | D20: [R$] | E20: =E5+E13 -> 1.8967027e+08 | F20: =F5+F13 -> 2.3774071e+08 | G20: =G5+G13 -> 2.6956144e+08 | H20: =H5+H13 -> 3.1806295e+08 | I20: =I5+I13 -> 3.6872611e+08 | J20: =J5+J13 -> 4.2293342e+08 | K20: =K5+K13 -> 4.7678369e+08 | L20: =L5+L13 -> 5.3426529e+08 | ... P20: =P5+P13 -> 7.3735123e+08
C21: % receita bruta | D21: [%] | E21: =E20/E$5 -> 0.75933333 | F21: =F20/F$5 -> 0.7574 | G21: =G20/G$5 -> 0.7636 | H21: =H20/H$5 -> 0.75966667 | I21: =I20/I$5 -> 0.75966667 | J21: =J20/J$5 -> 0.75966667 | K21: =K20/K$5 -> 0.75966667 | L21: =L20/L$5 -> 0.75966667 | ... P21: =P20/P$5 -> 0.75966667
C23: Custos operacionais | D23: [R$] | E23: =E26+E28 -> -1.4924686e+08 | F23: =F26+F28 -> -1.8176446e+08 | G23: =G26+G28 -> -2.0878504e+08 | H23: =H26+H28 -> -2.4609444e+08 | I23: =I26+I28 -> -2.8521146e+08 | J23: =J26+J28 -> -3.270641e+08 | K23: =K26+K28 -> -3.6857952e+08 | L23: =L26+L28 -> -4.1293959e+08 | ... P23: =P26+P28 -> -5.6945389e+08
C24: % receita bruta | D24: [%] | E24: =E23/E$5 -> -0.5975007 | F24: =F23/F$5 -> -0.57906952 | G24: =G23/G$5 -> -0.5914357 | H24: =H23/H$5 -> -0.58777592 | I24: =I23/I$5 -> -0.58760592 | J24: =J23/J$5 -> -0.58746764 | K24: =K23/K$5 -> -0.58726333 | L24: =L23/L$5 -> -0.58715483 | ... P24: =P23/P$5 -> -0.58668802
C26: COGS | D26: [R$] | E26: =Histórico!E16 -> -1.4322686e+08 | F26: =Histórico!F16 -> -1.7408371e+08 | G26: =Histórico!G16 -> -2.0075902e+08 | H26: =Histórico!H16 -> -2.363491e+08 | I26: =I$5*I27 -> -2.7399634e+08 | J26: =J$5*J27 -> -3.142772e+08 | K26: =K$5*K27 -> -3.5429275e+08 | L26: =L$5*L27 -> -3.970067e+08 | M26: =M$5*M27 -> -4.3762357e+08 | N26: =N$5*N27 -> -4.7570938e+08 | O26: =O$5*O27 -> -5.1257449e+08 | P26: =P$5*P27 -> -5.4791764e+08
C27: % receita bruta | D27: [%] | E27: =E26/E$5 -> -0.5734 | F27: =F26/F$5 -> -0.5546 | G27: =G26/G$5 -> -0.5687 | H27: =H26/H$5 -> -0.5645 | I27: =H27 -> -0.5645 | J27: =I27 -> -0.5645 | K27: =J27 -> -0.5645 | L27: =K27 -> -0.5645 | M27: =L27 -> -0.5645 | N27: =M27 -> -0.5645 | O27: =N27 -> -0.5645 | P27: =O27 -> -0.5645
C28: Pessoal | D28: [R$] | E28: =Histórico!E17 -> -6020000 | F28: =Histórico!F17 -> -7680750 | G28: =Histórico!G17 -> -8026018 | H28: =Histórico!H17 -> -9745335.6 | I28: =I30*I32 -> -11215124 | J28: =J30*J32 -> -12786903 | K28: =K30*K32 -> -14286772 | L28: =L30*L32 -> -15932896 | M28: =M30*M32 -> -17444885 | N28: =N30*N32 -> -18799658 | O28: =O30*O32 -> -20129784 | P28: =P30*P32 -> -21536241
C29: % receita bruta | D29: [%] | E29: =E28/E$5 -> -0.024100703 | F29: =F28/F$5 -> -0.024469515 | G29: =G28/G$5 -> -0.022735697 | H29: =H28/H$5 -> -0.023275916 | I29: =I28/I$5 -> -0.02310592 | J29: =J28/J$5 -> -0.022967643 | K29: =K28/K$5 -> -0.02276333 | L29: =L28/L$5 -> -0.022654831 | ... P29: =P28/P$5 -> -0.022188021
C30: # funcionários | D30: [#] | E30: =Histórico!E18 -> 172 | F30: =Histórico!F18 -> 210 | G30: =Histórico!G18 -> 211 | H30: =Histórico!H18 -> 244 | I30: =ROUND(I8/I31,0) -> 270 | J30: =ROUND(J8/J31,0) -> 296 | K30: =ROUND(K8/K31,0) -> 318 | L30: =ROUND(L8/L31,0) -> 341 | M30: =ROUND(M8/M31,0) -> 359 | N30: =ROUND(N8/N31,0) -> 372 | O30: =ROUND(O8/O31,0) -> 383 | P30: =ROUND(P8/P31,0) -> 394
C31: Qtd produzida / func. | D31: [#] | E31: =E8/E30 -> 706.68605 | F31: =F8/F30 -> 699.38095 | G31: =G8/G30 -> 731.61137 | H31: =H8/H30 -> 714.63115 | I31: 720 | J31: 725 | K31: 730 | L31: 735 | M31: 740 | N31: 745 | O31: 750 | P31: =O31 -> 750
C32: Custo médio / funcionário | D32: [R$ / FTE] | E32: =E28/E30 -> -35000 | F32: =F28/F30 -> -36575 | G32: =G28/G30 -> -38038 | H32: =H28/H30 -> -39939.9 | I32: =H32*(1+I33) -> -41537.496 | J32: =I32*(1+J33) -> -43198.996 | K32: =J32*(1+K33) -> -44926.956 | L32: =K32*(1+L33) -> -46724.034 | M32: =L32*(1+M33) -> -48592.995 | N32: =M32*(1+N33) -> -50536.715 | O32: =N32*(1+O33) -> -52558.184 | P32: =O32*(1+P33) -> -54660.511
C33: Crescimento custo médio / func. | D33: [%] | F33: =F32/E32-1 -> 0.045 | G33: =G32/F32-1 -> 0.04 | H33: =H32/G32-1 -> 0.05 | I33: 0.04 | J33: =I33 -> 0.04 | K33: =J33 -> 0.04 | L33: =K33 -> 0.04 | M33: =L33 -> 0.04 | N33: =M33 -> 0.04 | O33: =N33 -> 0.04 | P33: =O33 -> 0.04
C35: Lucro Bruto | D35: [R$] | E35: =E20+E23 -> 40423404 | F35: =F20+F23 -> 55976256 | G35: =G20+G23 -> 60776398 | H35: =H20+H23 -> 71968511 | I35: =I20+I23 -> 83514641 | J35: =J20+J23 -> 95869312 | K35: =K20+K23 -> 1.0820417e+08 | L35: =L20+L23 -> 1.2132569e+08 | ... P35: =P20+P23 -> 1.6789735e+08
C36: Margem bruta | D36: [%] | E36: =E35/E$20 -> 0.21312462 | F36: =F35/F$20 -> 0.23545086 | G36: =G35/G$20 -> 0.22546399 | H36: =H35/H$20 -> 0.22627128 | I36: =I35/I$20 -> 0.22649506 | J36: =J35/J$20 -> 0.22667708 | K36: =K35/K$20 -> 0.22694603 | L36: =L35/L$20 -> 0.22708886 | ... P36: =P35/P$20 -> 0.22770335
C38: Despesas Operacionais (SG&A) | D38: [R$] | E38: =E41+E56 -> -19277517 | F38: =F41+F56 -> -22537634 | G38: =G41+G56 -> -26102116 | H38: =H41+H56 -> -29072444 | I38: =I41+I56 -> -32335043 | J38: =J41+J56 -> -35812134 | K38: =K41+K56 -> -39530627 | L38: =L41+L56 -> -43191805 | ... P38: =P41+P56 -> -57093455
C39: % receita bruta | D39: [%] | E39: =E38/E$5 -> -0.077176364 | F39: =F38/F$5 -> -0.071800929 | G39: =G38/G$5 -> -0.073940752 | H39: =H38/H$5 -> -0.069437092 | I39: =I38/I$5 -> -0.066618159 | J39: =J38/J$5 -> -0.06432522 | K39: =K38/K$5 -> -0.062984746 | L39: =L38/L$5 -> -0.061414011 | ... P39: =P38/P$5 -> -0.058821349
C41: Despesas comerciais | D41: [R$] | E41: =SUM(E43,E49,E51,E53) -> -10441128 | F41: =SUM(F43,F49,F51,F53) -> -13126312 | G41: =SUM(G43,G49,G51,G53) -> -16031489 | H41: =SUM(H43,H49,H51,H53) -> -18181382 | I41: =SUM(I43,I49,I51,I53) -> -21008339 | J41: =SUM(J43,J49,J51,J53) -> -24032363 | K41: =SUM(K43,K49,K51,K53) -> -27081569 | L41: =SUM(L43,L49,L51,L53) -> -30244785 | ... P41: =SUM(P43,P49,P51,P53) -> -41465249
C42: % receita bruta | D42: [%] | E42: =E41/E$5 -> -0.041800419 | F42: =F41/F$5 -> -0.041818116 | G42: =G41/G$5 -> -0.045413191 | H42: =H41/H$5 -> -0.043424706 | I42: =I41/I$5 -> -0.043282357 | J42: =J41/J$5 -> -0.04316657 | K42: =K41/K$5 -> -0.043149475 | L42: =L41/L$5 -> -0.043004769 | ... P42: =P41/P$5 -> -0.042720167
C43: Pessoal | D43: [R$] | E43: =Histórico!E25 -> -2448000 | F43: =Histórico!F25 -> -3144592 | G43: =Histórico!G25 -> -3428891.7 | H43: =Histórico!H25 -> -3987875.6 | I43: =I44*I47 -> -4553997.5 | J43: =J44*J47 -> -5159028.6 | K43: =K44*K47 -> -5805175.8 | L43: =L44*L47 -> -6403284.9 | M43: =M44*M47 -> -7039954.3 | N43: =N44*N47 -> -7519432.3 | O43: =O44*O47 -> -8026004.6 | P43: =P44*P47 -> -8561071.6
C44: # funcionários | D44: [#] | E44: =Histórico!E26 -> 36 | F44: =Histórico!F26 -> 44 | G44: =Histórico!G26 -> 46 | H44: =Histórico!H26 -> 51 | I44: =ROUND(I8/I45,0) -> 56 | J44: =ROUND(J8/J45,0) -> 61 | K44: =ROUND(K8/K45,0) -> 66 | L44: =ROUND(L8/L45,0) -> 70 | M44: =ROUND(M8/M45,0) -> 74 | N44: =ROUND(N8/N45,0) -> 76 | O44: =ROUND(O8/O45,0) -> 78 | P44: =ROUND(P8/P45,0) -> 80
C45: Qtd vendida / func. | D45: [#] | E45: =E8/E44 -> 3376.3889 | F45: =F8/F44 -> 3337.9545 | G45: =G8/G44 -> 3355.8696 | H45: =H8/H44 -> 3419.0196 | I45: =ROUND(H45*(1+I46),0) -> 3453 | J45: =ROUND(I45*(1+J46),0) -> 3488 | K45: =ROUND(J45*(1+K46),0) -> 3523 | L45: =ROUND(K45*(1+L46),0) -> 3558 | M45: =ROUND(L45*(1+M46),0) -> 3594 | N45: =ROUND(M45*(1+N46),0) -> 3630 | O45: =ROUND(N45*(1+O46),0) -> 3666 | P45: =ROUND(O45*(1+P46),0) -> 3703
C46: Crescimento qtd vendida/ func. | D46: [%] | F46: =F45/E45-1 -> -0.011383269 | G46: =G45/F45-1 -> 0.0053670652 | H46: =H45/G45-1 -> 0.018817788 | I46: 0.01 | J46: =I46 -> 0.01 | K46: =J46 -> 0.01 | L46: =K46 -> 0.01 | M46: =L46 -> 0.01 | N46: =M46 -> 0.01 | O46: =N46 -> 0.01 | P46: =O46 -> 0.01
C47: Custo médio / funcionário | D47: [R$ / FTE] | E47: =E43/E44 -> -68000 | F47: =F43/F44 -> -71468 | G47: =G43/G44 -> -74541.124 | H47: =H43/H44 -> -78193.639 | I47: =H47*(1+I48) -> -81321.385 | J47: =I47*(1+J48) -> -84574.24 | K47: =J47*(1+K48) -> -87957.21 | L47: =K47*(1+L48) -> -91475.498 | M47: =L47*(1+M48) -> -95134.518 | N47: =M47*(1+N48) -> -98939.899 | O47: =N47*(1+O48) -> -102897.49 | P47: =O47*(1+P48) -> -107013.39
C48: Crescimento custo médio / func. | D48: [%] | F48: =F47/E47-1 -> 0.051 | G48: =G47/F47-1 -> 0.043 | H48: =H47/G47-1 -> 0.049 | I48: 0.04 | J48: =I48 -> 0.04 | K48: =J48 -> 0.04 | L48: =K48 -> 0.04 | M48: =L48 -> 0.04 | N48: =M48 -> 0.04 | O48: =N48 -> 0.04 | P48: =O48 -> 0.04
...
